Workbook

Sheet Einführung
A1: Formblatt für die Übermittlung von Änderungsanträgen zu den Entscheidungsbaum-Diagrammen und Codelisten
A2: Name: | C2: Unternehmen:
A3: Vorname: | C3: E-Mail:
A4: Kürzel:* | C4: Telefon:
A7: Hinweis: Gegenstand der vorliegenden Änderungen sind ausschließlich die gültigen EDIFACT-Nachrichtentypen bzw. die von der edi@energy erstellten Dokumente. (Dieses ist in der Zeile im Änderungsantrag - Tabelle Änderungsanträge - auszuwählen) *Kürzel: (Pflichtangabe) Das oben angegebene Kürzel ist in jedem Änderungsantrag anzugeben. 1.) Ausschließlich ausreichend begründete Änderungen können berücksichtigt werden. 2.) Ausschließlich weiter zu bearbeitende Dateien (im Format „.xls“ oder „.xlsx“ werden berücksichtigt). Sollten Sie Ihre Anmerkungen zusätzlich als pdf übermitteln wollen, so ist dies erlaubt. 3.) Bitte senden Sie diese Datei per Email an: maximilian.krug@bdew.de

Sheet Änderungsantrag
A1: Änd-ID | B1: Projekt-auftrag | C1: Dokument | D1: Version des Dokumentes | E1: Seite | F1: Kapitel | G1: EBD | H1: Bisheriger Inhalt | I1: Vorgeschlagene Änderung | J1: Herleitung der Änderung | K1: Einreicher | L1: Anmerkung
C2: Entscheidungsbaum-Diagramme und Codelisten | D2: 2.0 | E2: 93 | F2: 4.2 SD: Stammdatensynchronisation | G2: E_0453_Änderung prüfen | H2: […] Nr. 22 Prüfschritt Entspricht das Bilanzierungsverfahren dem gültigen Bilanzierungsverfahren zur Datenaggregation beim ÜNB? Prüfergebnis ja -> 23 nein -> 23 Code A09 Hinweis Bilanzierungsverfahren nicht gültig Nr. 23 Prüfschritt Ist das angegebene normierte Profil zum angegebenen Zeitpunkt für das Bilanzierungsgebiet Bestandteil der Profildefinitionsliste des Netzbetreibers? Prüfergebnis ja -> 25 nein -> 25 Code A10 Hinweis Normiertes Profil liegt nicht vor | I2: […] Nr. 22 Prüfschritt Entspricht das Bilanzierungsverfahren dem gültigen Bilanzierungsverfahren zur Datenaggregation beim ÜNB? Prüfergebnis ja -> 23 nein -> 23 Code A09 Hinweis Bilanzierungsverfahren nicht gültig Nr. 23 Prüfschritt Wird die Marktlokation auf grundlage von profilen bilanziert? Prüfergebnis ja -> 24 nein ->27 Nr. 24 Prüfschritt Ist das angegebene normierte Profil zum angegebenen Zeitpunkt für das Bilanzierungsgebiet Bestandteil der Profildefinitionsliste des Netzbetreibers? Prüfergebnis ja -> 25 nein -> 25 Code A10 Hinweis Normiertes Profil liegt nicht vor | J2: Die neue Frage (23) ist erforderlich, damit die nächsten Fragen in der richtigen Reihenfolge erfolgen. | K2: BDEW | M2: Beispiel für die Ausfüllung des Formulars
K3: =IF(Einführung!B4<>"",Einführung!B4,"")
K4: =IF(Einführung!B4<>"",Einführung!B4,"")
K5: =IF(Einführung!B4<>"",Einführung!B4,"")
K6: =IF(Einführung!B4<>"",Einführung!B4,"")
K7: =IF(Einführung!B4<>"",Einführung!B4,"")
K8: =IF(Einführung!B4<>"",Einführung!B4,"")
K9: =IF(Einführung!B4<>"",Einführung!B4,"")
K10: =IF(Einführung!B4<>"",Einführung!B4,"")
K11: =IF(Einführung!B4<>"",Einführung!B4,"")
K12: =IF(Einführung!B4<>"",Einführung!B4,"")
K13: =IF(Einführung!B4<>"",Einführung!B4,"")
K14: =IF(Einführung!B4<>"",Einführung!B4,"")
K15: =IF(Einführung!B4<>"",Einführung!B4,"")
K16: =IF(Einführung!B4<>"",Einführung!B4,"")
K17: =IF(Einführung!B4<>"",Einführung!B4,"")
K18: =IF(Einführung!B4<>"",Einführung!B4,"")
K19: =IF(Einführung!B4<>"",Einführung!B4,"")
K20: =IF(Einführung!B4<>"",Einführung!B4,"")
K21: =IF(Einführung!B4<>"",Einführung!B4,"")
K22: =IF(Einführung!B4<>"",Einführung!B4,"")
K23: =IF(Einführung!B4<>"",Einführung!B4,"")
K24: =IF(Einführung!B4<>"",Einführung!B4,"")
K25: =IF(Einführung!B4<>"",Einführung!B4,"")
K26: =IF(Einführung!B4<>"",Einführung!B4,"")
K27: =IF(Einführung!B4<>"",Einführung!B4,"")
K28: =IF(Einführung!B4<>"",Einführung!B4,"")
K29: =IF(Einführung!B4<>"",Einführung!B4,"")
K30: =IF(Einführung!B4<>"",Einführung!B4,"")
K31: =IF(Einführung!B4<>"",Einführung!B4,"")
K32: =IF(Einführung!B4<>"",Einführung!B4,"")
K33: =IF(Einführung!B4<>"",Einführung!B4,"")
K34: =IF(Einführung!B4<>"",Einführung!B4,"")
K35: =IF(Einführung!B4<>"",Einführung!B4,"")
K36: =IF(Einführung!B4<>"",Einführung!B4,"")
K37: =IF(Einführung!B4<>"",Einführung!B4,"")
K38: =IF(Einführung!B4<>"",Einführung!B4,"")
K39: =IF(Einführung!B4<>"",Einführung!B4,"")
K40: =IF(Einführung!B4<>"",Einführung!B4,"")
...

Sheet Wertetabelle
A1: Dokument
A2: Entscheidungsbaum-Diagramme und Codelisten | B2: E_0003_Bestellung der Aggregationsebene RZ prüfen
B3: E_0004_Marktlokationen mit LF-CL abgleichen
B4: E_0005_Erstabonnierung prüfen
B5: E_0007_LF-SZR (Kategorie A) prüfen
B6: E_0008_NZR prüfen
B7: E_0009_MaBiS-ZP Deaktivierung prüfen
B8: E_0010_MaBiS-ZP Deaktivierung prüfen
B9: E_0011_MaBiS-ZP Aktivierung prüfen
B10: E_0012_MaBiS-ZP Deaktivierung prüfen
B11: E_0013_Einzelanforderung prüfen
B12: E_0014_Marktlokationen mit LF-CL abgleichen
B13: E_0015_MaBiS-ZP Aktivierung prüfen
B14: E_0016_Einzelanforderung prüfen
... B494: Sonstiges
